<?xml version="1.0" ?>
<!-- =================================================================================== -->
<!-- |    This document was autogenerated by xacro from models/two_dof.urdf.xacro      | -->
<!-- |    EDITING THIS FILE BY HAND IS NOT RECOMMENDED                                 | -->
<!-- =================================================================================== -->
<robot name="two_dof_robot">
  <!-- Referencia Robot -->
  <link name="base_footprint">
  </link>
  <!-- Base Robot -->
  <link name="base_link">
    <visual>
      <origin rpy="0 0 0" xyz="0 0 0.15"/>
      <geometry>
        <box size="0.1 0.1 0.3"/>
      </geometry>
      <material name="Cyan">
        <color rgba="0 1.0 1.0 1.0"/>
      </material>
    </visual>
    <collision>
      <origin rpy="0 0 0" xyz="0 0 0.15"/>
      <geometry>
        <box size="0.1 0.1 0.3"/>
      </geometry>
    </collision>
    <inertial>
      <origin rpy="1.5707963267948966 0 1.5707963267948966" xyz="0 0 0"/>
      <mass value="5"/>
      <inertia ixx="0.04166666666666667" ixy="0.0" ixz="0.0" iyy="0.008333333333333335" iyz="0.0" izz="0.04166666666666667"/>
    </inertial>
  </link>
  <joint name="base_link_joint" type="fixed">
    <parent link="base_footprint"/>
    <child link="base_link"/>
  </joint>
  <!-- Arm Robot -->
  <link name="arm_link">
    <visual>
      <origin rpy="0 0 0" xyz="0 0 0"/>
      <geometry>
        <box size="0.1 0.1 0.5"/>
      </geometry>
      <material name="Cyan">
        <color rgba="0 1.0 1.0 1.0"/>
      </material>
    </visual>
    <collision>
      <origin rpy="0 0 0" xyz="0 0 0"/>
      <geometry>
        <box size="0.1 0.1 0.5"/>
      </geometry>
    </collision>
    <inertial>
      <origin rpy="1.5707963267948966 0 1.5707963267948966" xyz="0 0 0"/>
      <mass value="5"/>
      <inertia ixx="0.10833333333333334" ixy="0.0" ixz="0.0" iyy="0.008333333333333335" iyz="0.0" izz="0.10833333333333334"/>
    </inertial>
  </link>
  <joint name="arm_joint" type="revolute">
    <origin rpy="0.0 0.0 0.0" xyz="0.1 0.0 0.5"/>
    <parent link="base_link"/>
    <child link="arm_link"/>
    <axis xyz="1.0 0.0 0.0"/>
    <limit effort="1.0" lower="0.0" upper="3.15" velocity="10.0"/>
  </joint>
  <!-- Forearm Robot -->
  <link name="forearm_link">
    <visual>
      <origin rpy="0 0 0" xyz="0 0 0"/>
      <geometry>
        <box size="0.1 0.1 0.4"/>
      </geometry>
      <material name="Cyan">
        <color rgba="0 1.0 1.0 1.0"/>
      </material>
    </visual>
    <collision>
      <origin rpy="0 0 0" xyz="0 0 0"/>
      <geometry>
        <box size="0.1 0.1 0.4"/>
      </geometry>
    </collision>
    <inertial>
      <origin rpy="1.5707963267948966 0 1.5707963267948966" xyz="0 0 0"/>
      <mass value="5"/>
      <inertia ixx="0.07083333333333336" ixy="0.0" ixz="0.0" iyy="0.008333333333333335" iyz="0.0" izz="0.07083333333333336"/>
    </inertial>
  </link>
  <joint name="forearm_joint" type="revolute">
    <origin rpy="0.0 0.0 0.0" xyz="0.1 0.0 0.4"/>
    <parent link="arm_link"/>
    <child link="forearm_link"/>
    <axis xyz="1.0 0.0 0.0"/>
    <limit effort="1.0" lower="0.0" upper="3.15" velocity="10.0"/>
  </joint>
</robot>
